root - ERROR - Traceback (most recent call last):
  File ".\Luna.py", line 186, in respond_loops
    self.wait.until(message_loaded(message_list, prev_msg_ID))
  File "C:\Users\smthcol\AppData\Local\Programs\Python\Python37-32\lib\site-packages\selenium\webdriver\support\wait.py", line 71, in until
    value = method(self._driver)
  File "C:\Users\smthcol\Documents\Luna\Windows\waits\message_loaded.py", line 9, in __call__
    messages = self.message_list.find_elements_by_class_name("ChatMessageList__messageContainer")
  File "C:\Users\smthcol\AppData\Local\Programs\Python\Python37-32\lib\site-packages\selenium\webdriver\remote\webelement.py", line 413, in find_elements_by_class_name
    return self.find_elements(by=By.CLASS_NAME, value=name)
  File "C:\Users\smthcol\AppData\Local\Programs\Python\Python37-32\lib\site-packages\selenium\webdriver\remote\webelement.py", line 685, in find_elements
    {"using": by, "value": value})['value']
  File "C:\Users\smthcol\AppData\Local\Programs\Python\Python37-32\lib\site-packages\selenium\webdriver\remote\webelement.py", line 633, in _execute
    return self._parent.execute(command, params)
  File "C:\Users\smthcol\AppData\Local\Programs\Python\Python37-32\lib\site-packages\selenium\webdriver\remote\webdriver.py", line 321, in execute
    self.error_handler.check_response(response)
  File "C:\Users\smthcol\AppData\Local\Programs\Python\Python37-32\lib\site-packages\selenium\webdriver\remote\errorhandler.py", line 242, in check_response
    raise exception_class(message, screen, stacktrace)
selenium.common.exceptions.WebDriverException: Message: Failed to decode response from marionette


During handling of the above exception, another exception occurred:

Traceback (most recent call last):
  File ".\Luna.py", line 195, in respond_loops
    big_message_list = self.driver.find_element_by_class_name("ChatMessageList.ChatContainer__messagesList")
  File "C:\Users\smthcol\AppData\Local\Programs\Python\Python37-32\lib\site-packages\selenium\webdriver\remote\webdriver.py", line 564, in find_element_by_class_name
    return self.find_element(by=By.CLASS_NAME, value=name)
  File "C:\Users\smthcol\AppData\Local\Programs\Python\Python37-32\lib\site-packages\selenium\webdriver\remote\webdriver.py", line 978, in find_element
    'value': value})['value']
  File "C:\Users\smthcol\AppData\Local\Programs\Python\Python37-32\lib\site-packages\selenium\webdriver\remote\webdriver.py", line 321, in execute
    self.error_handler.check_response(response)
  File "C:\Users\smthcol\AppData\Local\Programs\Python\Python37-32\lib\site-packages\selenium\webdriver\remote\errorhandler.py", line 242, in check_response
    raise exception_class(message, screen, stacktrace)
selenium.common.exceptions.InvalidSessionIdException: Message: Tried to run command without establishing a connection


During handling of the above exception, another exception occurred:

Traceback (most recent call last):
  File ".\Luna.py", line 353, in <module>
    bot.respond_loops()
  File ".\Luna.py", line 205, in respond_loops
    self.driver.get("https://app.chime.aws")
  File "C:\Users\smthcol\AppData\Local\Programs\Python\Python37-32\lib\site-packages\selenium\webdriver\remote\webdriver.py", line 333, in get
    self.execute(Command.GET, {'url': url})
  File "C:\Users\smthcol\AppData\Local\Programs\Python\Python37-32\lib\site-packages\selenium\webdriver\remote\webdriver.py", line 321, in execute
    self.error_handler.check_response(response)
  File "C:\Users\smthcol\AppData\Local\Programs\Python\Python37-32\lib\site-packages\selenium\webdriver\remote\errorhandler.py", line 242, in check_response
    raise exception_class(message, screen, stacktrace)
selenium.common.exceptions.InvalidSessionIdException: Message: Tried to run command without establishing a connection


